17394 MainProcess 2023-09-05 08:49:45,070
Traceback (most recent call last):
  File "/data/data/com.termux/files/usr/lib/python3.11/site-packages/pyarmor/cli/core/__init__.py", line 75, in _import_pytransform3
    return __import__(
           ^^^^^^^^^^^
ModuleNotFoundError: No module named 'pyarmor.cli.core.pytransform3'

During handling of the above exception, another exception occurred:

Traceback (most recent call last):
  File "/data/data/com.termux/files/usr/lib/python3.11/site-packages/pyarmor/cli/__main__.py", line 702, in main
    main_entry(sys.argv[1:])
  File "/data/data/com.termux/files/usr/lib/python3.11/site-packages/pyarmor/cli/__main__.py", line 690, in main_entry
    return args.func(ctx, args)
           ^^^^^^^^^^^^^^^^^^^^
  File "/data/data/com.termux/files/usr/lib/python3.11/site-packages/pyarmor/cli/__main__.py", line 229, in cmd_gen
    builder.process(options)
  File "/data/data/com.termux/files/usr/lib/python3.11/site-packages/pyarmor/cli/generate.py", line 147, in process
    Pytransform3.pre_build(self.ctx)
  File "/data/data/com.termux/files/usr/lib/python3.11/site-packages/pyarmor/cli/core/__init__.py", line 117, in pre_build
    m = Pytransform3.init(ctx)
        ^^^^^^^^^^^^^^^^^^^^^^
  File "/data/data/com.termux/files/usr/lib/python3.11/site-packages/pyarmor/cli/core/__init__.py", line 95, in init
    Pytransform3._pytransform3 = m = _import_pytransform3()
                                     ^^^^^^^^^^^^^^^^^^^^^^
  File "/data/data/com.termux/files/usr/lib/python3.11/site-packages/pyarmor/cli/core/__init__.py", line 82, in _import_pytransform3
    return __import__(
           ^^^^^^^^^^^
ImportError: dlopen failed: cannot locate symbol "PyFloat_Type" referenced by "/data/data/com.termux/files/usr/lib/python3.11/site-packages/pyarmor/cli/core/android/aarch64/pytransform3.so"...
